2024-10-08 17:27:07,346 - INFO - PYTHONPATH set to default: envy
2024-10-08 17:27:53,668 - INFO - PYTHONPATH set to default: envy
2024-10-08 17:27:53,708 - INFO - Successfully executed command: /home/formidablepencil/envy/venv/bin/python3 main.py
2024-10-08 17:35:45,852 - INFO - PYTHONPATH set to default: envy
2024-10-08 17:36:27,097 - INFO - PYTHONPATH set to default: envy
2024-10-08 17:36:27,122 - INFO - Successfully executed command: /home/formidablepencil/envy/venv/bin/python3 main.py
2024-10-08 17:37:53,064 - INFO - PYTHONPATH set to default: envy
2024-10-08 17:37:53,097 - ERROR - Error running script: Command '['/home/formidablepencil/envy/venv/bin/python3', 'main.py']' returned non-zero exit status 1.
2024-10-08 17:37:53,097 - ERROR - Command output: 
2024-10-08 17:37:53,097 - ERROR - Command error: Traceback (most recent call last):
  File "/home/formidablepencil/envy/central_ai_manager/main.py", line 3, in <module>
    from testme import testmeplz
ModuleNotFoundError: No module named 'testme'

2024-10-08 17:39:15,122 - INFO - PYTHONPATH set to default: envy
2024-10-08 17:39:15,171 - INFO - Successfully executed command: /home/formidablepencil/envy/venv/bin/python3 main.py
2024-10-08 17:40:04,422 - INFO - PYTHONPATH set to default: envy
2024-10-08 17:40:04,447 - INFO - Successfully executed command: /home/formidablepencil/envy/venv/bin/python3 main.py
2024-10-08 17:40:46,813 - INFO - PYTHONPATH set to default: envy
